[{"name": "test.test_operations_on_series.OperationsOnSeries.test_creation", "status": "passed", "message": "", "passed": true, "points": ["p03-14.1"], "backtrace": []}, {"name": "test.test_operations_on_series.OperationsOnSeries.test_main", "status": "failed", "message": "Expected '__add__' to have been called.", "passed": false, "points": ["p03-14.1"], "backtrace": ["  File \"C:\\Users\\Tec\\AppData\\Local\\Programs\\Python\\Python311\\Lib\\unittest\\case.py\", line 57, in testPartExecutor\n    yield\n", "  File \"C:\\Users\\Tec\\AppData\\Local\\Programs\\Python\\Python311\\Lib\\unittest\\case.py\", line 623, in run\n    self._callTestMethod(testMethod)\n", "  File \"C:\\Users\\Tec\\AppData\\Local\\Programs\\Python\\Python311\\Lib\\unittest\\case.py\", line 579, in _callTestMethod\n    if method() is not None:\n       ^^^^^^^^\n", "  File \"C:\\Users\\Tec\\Desktop\\GhRep\\Python-og-DataAnalyse_Oliver\\excercises\\part03\\e14_operations_on_series\\test\\test_operations_on_series.py\", line 73, in test_main\n    padd.assert_called()\n", "  File \"C:\\Users\\Tec\\AppData\\Local\\Programs\\Python\\Python311\\Lib\\unittest\\mock.py\", line 892, in assert_called\n    raise AssertionError(msg)\n"]}, {"name": "test.test_operations_on_series.OperationsOnSeries.test_modification", "status": "passed", "message": "", "passed": true, "points": ["p03-14.1"], "backtrace": []}]