[{"name": "unittest.loader._FailedTest.test.test_extract_numbers", "status": "errored", "message": "Failed to import test module: test.test_extract_numbers\nTraceback (most recent call last):\n  File \"C:\\Program Files\\WindowsApps\\PythonSoftwareFoundation.Python.3.11_3.11.1008.0_x64__qbz5n2kfra8p0\\Lib\\unittest\\loader.py\", line 407, in _find_test_path\n    module = self._get_module_from_name(name)\n             ^^^^^^^^^^^^^^^^^^^^^^^^^^^^^^^^\n  File \"C:\\Program Files\\WindowsApps\\PythonSoftwareFoundation.Python.3.11_3.11.1008.0_x64__qbz5n2kfra8p0\\Lib\\unittest\\loader.py\", line 350, in _get_module_from_name\n    __import__(name)\n  File \"H:\\GitHub repositories\\PythonData-H4\\e30_extract_numbers\\test\\test_extract_numbers.py\", line 3, in <module>\n    import numpy as np\nModuleNotFoundError: No module named 'numpy'\n", "passed": false, "points": [], "backtrace": ["  File \"C:\\Program Files\\WindowsApps\\PythonSoftwareFoundation.Python.3.11_3.11.1008.0_x64__qbz5n2kfra8p0\\Lib\\unittest\\case.py\", line 57, in testPartExecutor\n    yield\n", "  File \"C:\\Program Files\\WindowsApps\\PythonSoftwareFoundation.Python.3.11_3.11.1008.0_x64__qbz5n2kfra8p0\\Lib\\unittest\\case.py\", line 623, in run\n    self._callTestMethod(testMethod)\n", "  File \"C:\\Program Files\\WindowsApps\\PythonSoftwareFoundation.Python.3.11_3.11.1008.0_x64__qbz5n2kfra8p0\\Lib\\unittest\\case.py\", line 579, in _callTestMethod\n    if method() is not None:\n       ^^^^^^^^\n", "  File \"C:\\Program Files\\WindowsApps\\PythonSoftwareFoundation.Python.3.11_3.11.1008.0_x64__qbz5n2kfra8p0\\Lib\\unittest\\loader.py\", line 34, in testFailure\n    raise self._exception\n"]}]